Workbook
Name Slicer_Product_Type: #N/A
Name Slicer_Product_Type1: #N/A
Name Slicer_Quarter: #N/A
Name Slicer_Sales_Rep: #N/A

Sheet Dashboard
B1: Mobility Sales Dashboard
B2: KPIs, discount effectiveness and key charts | Source: 'Mobility sales data' sheet (Table3) and pivots
B4: Net sales (EUR) | D4: Units | F4: € / unit | H4: Avg discount | J4: Best month | L4: Top rep
B5: =SUM(Table3[Total Sales (EUR)]) -> 36382530 | D5: =SUM(Table3[Units Sold]) -> 65480 | F5: =B5/D5 -> 555.62813 | H5: =SUM(Table3[Discount (EUR)])/SUM(Table3[Gross Sales (EUR)]) -> 0.040266413 | J5: =INDEX('Pivot Time'!M4:M15,MATCH(MAX('Pivot Time'!N4:N15),'Pivot Time'!N4:N15,0)) -> June | L5: =INDEX('Pivot Reps & Products'!J4:J7,MATCH(MAX('Pivot Reps & Products'!K4:K7),'Pivot Reps & Products'!K4:K7,0)) -> Liu, Fang
B7: Discount effectiveness
B8: Average units per order with vs without discount
B9: Product | C9: Units/order (no disc.) | D9: Units/order (with disc.) | E9: Uplift | F9: Avg discount (if >0)
B10: Electric Scooter | C10: =AVERAGEIFS(Table3[Units Sold],Table3[Product Type],$B10,Table3[Discount (%)],0) -> 635.55556 | D10: =AVERAGEIFS(Table3[Units Sold],Table3[Product Type],$B10,Table3[Discount (%)],">0") -> 644.16667 | E10: =IFERROR(D10/C10-1,"-") -> 0.013548951 | F10: =AVERAGEIFS(Table3[Discount (%)],Table3[Product Type],$B10,Table3[Discount (%)],">0")/100 -> 0.15
B11: Electric Skateboard | C11: =AVERAGEIFS(Table3[Units Sold],Table3[Product Type],$B11,Table3[Discount (%)],0) -> 439.16667 | D11: =AVERAGEIFS(Table3[Units Sold],Table3[Product Type],$B11,Table3[Discount (%)],">0") -> 440 | E11: =IFERROR(D11/C11-1,"-") -> 0.0018975332 | F11: =AVERAGEIFS(Table3[Discount (%)],Table3[Product Type],$B11,Table3[Discount (%)],">0")/100 -> 0.15
B12: Electric Unicycle | C12: =AVERAGEIFS(Table3[Units Sold],Table3[Product Type],$B12,Table3[Discount (%)],0) -> 288.88889 | D12: =AVERAGEIFS(Table3[Units Sold],Table3[Product Type],$B12,Table3[Discount (%)],">0") -> 281.66667 | E12: =IFERROR(D12/C12-1,"-") -> -0.025 | F12: =AVERAGEIFS(Table3[Discount (%)],Table3[Product Type],$B12,Table3[Discount (%)],">0")/100 -> 0.15
B13: Total | C13: =AVERAGEIFS(Table3[Units Sold],Table3[Discount (%)],0) -> 454.53704 | D13: =AVERAGEIFS(Table3[Units Sold],Table3[Discount (%)],">0") -> 455.27778 | E13: =IFERROR(D13/C13-1,"-") -> 0.0016296598 | F13: =AVERAGEIFS(Table3[Discount (%)],Table3[Discount (%)],">0")/100 -> 0.15
B49: Chart data (mirror of the pivots — do not edit)
B50: ='Pivot Time'!M3 -> Month | C50: ='Pivot Time'!N3 -> Sales (EUR) | E50: ='Pivot Time'!P3 -> Quarter | F50: ='Pivot Time'!Q3 -> Sales (EUR) | G50: ='Pivot Time'!R3 -> Discounts (EUR) | I50: ='Pivot Reps & Products'!J3 -> Sales Rep | J50: ='Pivot Reps & Products'!K3 -> Sales (EUR) | L50: ='Pivot Reps & Products'!M3 -> Product | M50: ='Pivot Reps & Products'!N3 -> Sales (EUR)
B51: ='Pivot Time'!M4 -> January | C51: ='Pivot Time'!N4 -> 2076593 | E51: ='Pivot Time'!P4 -> Q1 | F51: ='Pivot Time'!Q4 -> 7180763 | G51: ='Pivot Time'!R4 -> 230730 | I51: ='Pivot Reps & Products'!J4 -> Liu, Fang | J51: ='Pivot Reps & Products'!K4 -> 18770889 | L51: ='Pivot Reps & Products'!M4 -> Electric Scooter | M51: ='Pivot Reps & Products'!N4 -> 14904265
B52: ='Pivot Time'!M5 -> February | C52: ='Pivot Time'!N5 -> 2552085 | E52: ='Pivot Time'!P5 -> Q2 | F52: ='Pivot Time'!Q5 -> 10284291 | G52: ='Pivot Time'!R5 -> 0 | I52: ='Pivot Reps & Products'!J5 -> Bernard, Théo | J52: ='Pivot Reps & Products'!K5 -> 8059775 | L52: ='Pivot Reps & Products'!M5 -> Electric Skateboard | M52: ='Pivot Reps & Products'!N5 -> 12366531
B53: ='Pivot Time'!M6 -> March | C53: ='Pivot Time'!N6 -> 2552085 | E53: ='Pivot Time'!P6 -> Q3 | F53: ='Pivot Time'!Q6 -> 10141023 | G53: ='Pivot Time'!R6 -> 0 | I53: ='Pivot Reps & Products'!J6 -> Fischer, Jonas | J53: ='Pivot Reps & Products'!K6 -> 7068725 | L53: ='Pivot Reps & Products'!M6 -> Electric Unicycle | M53: ='Pivot Reps & Products'!N6 -> 9111734
B54: ='Pivot Time'!M7 -> April | C54: ='Pivot Time'!N7 -> 3167122 | E54: ='Pivot Time'!P7 -> Q4 | F54: ='Pivot Time'!Q7 -> 8776453 | G54: ='Pivot Time'!R7 -> 1295729 | I54: ='Pivot Reps & Products'!J7 -> Joshi, Sanya | J54: ='Pivot Reps & Products'!K7 -> 2483141
B55: ='Pivot Time'!M8 -> May | C55: ='Pivot Time'!N8 -> 3311633
B56: ='Pivot Time'!M9 -> June | C56: ='Pivot Time'!N9 -> 3805536
B57: ='Pivot Time'!M10 -> July | C57: ='Pivot Time'!N10 -> 3744231
B58: ='Pivot Time'!M11 -> August | C58: ='Pivot Time'!N11 -> 3308633
B59: ='Pivot Time'!M12 -> September | C59: ='Pivot Time'!N12 -> 3088159
B60: ='Pivot Time'!M13 -> October | C60: ='Pivot Time'!N13 -> 2817184
B61: ='Pivot Time'!M14 -> November | C61: ='Pivot Time'!N14 -> 2639595
B62: ='Pivot Time'!M15 -> December | C62: ='Pivot Time'!N15 -> 3319674

Sheet Mobility sales data
A1: Sales Rep ID | B1: Rep First Name | C1: Rep Last Name | D1: Sales Rep | E1: Month | F1: Product Type | G1: Min Speed (original, incomplete) | H1: Min Speed (mph) | I1: Speed | J1: Distance | K1: Min Speed (km/h) | L1: Max Speed (km/h) | M1: Speed Range (km/h) | N1: Distance (km) | O1: Shipping Address | P1: Street | Q1: City | R1: Postcode | S1: Country Code | T1: Country Name | U1: Continent | V1: Unit Price | W1: Currency | X1: Unit Price (local) | Y1: FX Rate (per EUR) | Z1: Unit Price (EUR) | AA1: Units Sold | AB1: Discount (%) | AC1: Gross Sales (EUR) | AD1: Total Sales (EUR) | AE1: Month No | AF1: Month (sorted) | AG1: Quarter | AH1: Discount (EUR) | AI1: Month (date)
A2: 1 | B2: Sanya | C2: Joshi | D2: =TRIM(Table3[[#This Row],[Rep Last Name]])&", "&TRIM(Table3[[#This Row],[Rep First Name]]) -> Joshi, Sanya | E2: January | F2: Electric Unicycle | G2: 15 mph | H2: =IF(Table3[[#This Row],[Min Speed (original, incomplete)]]="",_xlfn.IFNA(_xlfn.XLOOKUP(Table3[[#This Row],[Product Type]],Lookups!$G$2:$G$4,Lookups!$H$2:$H$4),"CHECK PRODUCT"),Table3[[#This Row],[Min Speed (original, incomplete)]]) -> 15 mph | I2: 30 mph | J2: 30 miles | K2: =ROUND(VALUE(SUBSTITUTE(Table3[[#This Row],[Min Speed (mph)]]," mph",""))*Lookups!$L$2,0) -> 24 | L2: =ROUND(VALUE(SUBSTITUTE(Table3[[#This Row],[Speed]]," mph",""))*Lookups!$L$2,0) -> 48 | M2: =Table3[[#This Row],[Min Speed (km/h)]]&" – "&Table3[[#This Row],[Max Speed (km/h)]]&" km/h" -> 24 – 48 km/h | N2: =IF(ISNUMBER(SEARCH("mile",Table3[[#This Row],[Distance]])),ROUND(VALUE(SUBSTITUTE(Table3[[#This Row],[Distance]]," miles",""))*Lookups!$L$3,0),ROUND(VALUE(SUBSTITUTE(Table3[[#This Row],[Distance]]," meters",""))*Lookups!$L$4,0)) -> 48 | O2: 456 Brigade Road, Bengaluru, 560001 | P2: =TRIM(LEFT(Table3[[#This Row],[Shipping Address]],FIND(",",Table3[[#This Row],[Shipping Address]])-1)) -> 456 Brigade Road | Q2: =TRIM(MID(Table3[[#This Row],[Shipping Address]],FIND(",",Table3[[#This Row],[Shipping Address]])+1,FIND(",",Table3[[#This Row],[Shipping Address]],FIND(",",Table3[[#This Row],[Shipping Address]])+1)-FIND(",",Table3[[#This Row],[Shipping Address]])-1)) -> Bengaluru | R2: =TRIM(MID(Table3[[#This Row],[Shipping Address]],FIND(",",Table3[[#This Row],[Shipping Address]],FIND(",",Table3[[#This Row],[Shipping Address]])+1)+1,20)) -> 560001 | S2: IN | T2: =_xlfn.IFNA(_xlfn.XLOOKUP(Table3[[#This Row],[Country Code]],Lookups!$A$2:$A$5,Lookups!$B$2:$B$5),"CHECK CODE") -> India | U2: =_xlfn.IFNA(_xlfn.XLOOKUP(Table3[[#This Row],[Country Code]],Lookups!$A$2:$A$5,Lookups!$C$2:$C$5),"CHECK CODE") -> Asia | V2: ₹30,000 | W2: =_xlfn.IFNA(_xlfn.XLOOKUP(Table3[[#This Row],[Country Code]],Lookups!$A$2:$A$5,Lookups!$D$2:$D$5),"CHECK CODE") -> INR | X2: =VALUE(MID(Table3[[#This Row],[Unit Price]],2,50)) -> 30000 | Y2: =_xlfn.IFNA(_xlfn.XLOOKUP(Table3[[#This Row],[Country Code]],Lookups!$A$2:$A$5,Lookups!$E$2:$E$5),"") -> 109.882 | Z2: =Table3[[#This Row],[Unit Price (local)]]/Table3[[#This Row],[FX Rate (per EUR)]] -> 273.02015 | AA2: 150 | AB2: 10 | AC2: =ROUND(Table3[[#This Row],[Unit Price (EUR)]]*Table3[[#This Row],[Units Sold]],0) -> 40953 | AD2: =ROUND(Table3[[#This Row],[Gross Sales (EUR)]]*(1-Table3[[#This Row],[Discount (%)]]/100),0) -> 36858 | AE2: =_xlfn.IFNA(_xlfn.XLOOKUP(Table3[[#This Row],[Month]],Lookups!$N$2:$N$13,Lookups!$O$2:$O$13),"CHECK MONTH") -> 1 | AF2: =TEXT(Table3[[#This Row],[Month No]],"00")&" - "&Table3[[#This Row],[Month]] -> 01 - January | AG2: =_xlfn.IFNA(_xlfn.XLOOKUP(Table3[[#This Row],[Month]],Lookups!$N$2:$N$13,Lookups!$P$2:$P$13),"CHECK MONTH") -> Q1 | AH2: =Table3[[#This Row],[Gross Sales (EUR)]]-Table3[[#This Row],[Total Sales (EUR)]] -> 4095 | AI2: =DATE(Lookups!$O$15,Table3[[#This Row],[Month No]],1) -> 45658
A3: 2 | B3: Sanya | C3: Joshi | D3: =TRIM(Table3[[#This Row],[Rep Last Name]])&", "&TRIM(Table3[[#This Row],[Rep First Name]]) -> Joshi, Sanya | E3: January | F3: Electric Scooter | G3: 20 mph | H3: =IF(Table3[[#This Row],[Min Speed (original, incomplete)]]="",_xlfn.IFNA(_xlfn.XLOOKUP(Table3[[#This Row],[Product Type]],Lookups!$G$2:$G$4,Lookups!$H$2:$H$4),"CHECK PRODUCT"),Table3[[#This Row],[Min Speed (original, incomplete)]]) -> 20 mph | I3: 35 mph | J3: 40 miles | K3: =ROUND(VALUE(SUBSTITUTE(Table3[[#This Row],[Min Speed (mph)]]," mph",""))*Lookups!$L$2,0) -> 32 | L3: =ROUND(VALUE(SUBSTITUTE(Table3[[#This Row],[Speed]]," mph",""))*Lookups!$L$2,0) -> 56 | M3: =Table3[[#This Row],[Min Speed (km/h)]]&" – "&Table3[[#This Row],[Max Speed (km/h)]]&" km/h" -> 32 – 56 km/h | N3: =IF(ISNUMBER(SEARCH("mile",Table3[[#This Row],[Distance]])),ROUND(VALUE(SUBSTITUTE(Table3[[#This Row],[Distance]]," miles",""))*Lookups!$L$3,0),ROUND(VALUE(SUBSTITUTE(Table3[[#This Row],[Distance]]," meters",""))*Lookups!$L$4,0)) -> 64 | O3: 457 Brigade Road, Bengaluru, 560001 | P3: =TRIM(LEFT(Table3[[#This Row],[Shipping Address]],FIND(",",Table3[[#This Row],[Shipping Address]])-1)) -> 457 Brigade Road | Q3: =TRIM(MID(Table3[[#This Row],[Shipping Address]],FIND(",",Table3[[#This Row],[Shipping Address]])+1,FIND(",",Table3[[#This Row],[Shipping Address]],FIND(",",Table3[[#This Row],[Shipping Address]])+1)-FIND(",",Table3[[#This Row],[Shipping Address]])-1)) -> Bengaluru | R3: =TRIM(MID(Table3[[#This Row],[Shipping Address]],FIND(",",Table3[[#This Row],[Shipping Address]],FIND(",",Table3[[#This Row],[Shipping Address]])+1)+1,20)) -> 560001 | S3: IN | T3: =_xlfn.IFNA(_xlfn.XLOOKUP(Table3[[#This Row],[Country Code]],Lookups!$A$2:$A$5,Lookups!$B$2:$B$5),"CHECK CODE") -> India | U3: =_xlfn.IFNA(_xlfn.XLOOKUP(Table3[[#This Row],[Country Code]],Lookups!$A$2:$A$5,Lookups!$C$2:$C$5),"CHECK CODE") -> Asia | V3: ₹25,000 | W3: =_xlfn.IFNA(_xlfn.XLOOKUP(Table3[[#This Row],[Country Code]],Lookups!$A$2:$A$5,Lookups!$D$2:$D$5),"CHECK CODE") -> INR | X3: =VALUE(MID(Table3[[#This Row],[Unit Price]],2,50)) -> 25000 | Y3: =_xlfn.IFNA(_xlfn.XLOOKUP(Table3[[#This Row],[Country Code]],Lookups!$A$2:$A$5,Lookups!$E$2:$E$5),"") -> 109.882 | Z3: =Table3[[#This Row],[Unit Price (local)]]/Table3[[#This Row],[FX Rate (per EUR)]] -> 227.51679 | AA3: 300 | AB3: 10 | AC3: =ROUND(Table3[[#This Row],[Unit Price (EUR)]]*Table3[[#This Row],[Units Sold]],0) -> 68255 | AD3: =ROUND(Table3[[#This Row],[Gross Sales (EUR)]]*(1-Table3[[#This Row],[Discount (%)]]/100),0) -> 61430 | AE3: =_xlfn.IFNA(_xlfn.XLOOKUP(Table3[[#This Row],[Month]],Lookups!$N$2:$N$13,Lookups!$O$2:$O$13),"CHECK MONTH") -> 1 | AF3: =TEXT(Table3[[#This Row],[Month No]],"00")&" - "&Table3[[#This Row],[Month]] -> 01 - January | AG3: =_xlfn.IFNA(_xlfn.XLOOKUP(Table3[[#This Row],[Month]],Lookups!$N$2:$N$13,Lookups!$P$2:$P$13),"CHECK MONTH") -> Q1 | AH3: =Table3[[#This Row],[Gross Sales (EUR)]]-Table3[[#This Row],[Total Sales (EUR)]] -> 6825 | AI3: =DATE(Lookups!$O$15,Table3[[#This Row],[Month No]],1) -> 45658
A4: 3 | B4: Sanya | C4: Joshi | D4: =TRIM(Table3[[#This Row],[Rep Last Name]])&", "&TRIM(Table3[[#This Row],[Rep First Name]]) -> Joshi, Sanya | E4: January | F4: Electric Skateboard | G4: 18 mph | H4: =IF(Table3[[#This Row],[Min Speed (original, incomplete)]]="",_xlfn.IFNA(_xlfn.XLOOKUP(Table3[[#This Row],[Product Type]],Lookups!$G$2:$G$4,Lookups!$H$2:$H$4),"CHECK PRODUCT"),Table3[[#This Row],[Min Speed (original, incomplete)]]) -> 18 mph | I4: 28 mph | J4: 25 miles | K4: =ROUND(VALUE(SUBSTITUTE(Table3[[#This Row],[Min Speed (mph)]]," mph",""))*Lookups!$L$2,0) -> 29 | L4: =ROUND(VALUE(SUBSTITUTE(Table3[[#This Row],[Speed]]," mph",""))*Lookups!$L$2,0) -> 45 | M4: =Table3[[#This Row],[Min Speed (km/h)]]&" – "&Table3[[#This Row],[Max Speed (km/h)]]&" km/h" -> 29 – 45 km/h | N4: =IF(ISNUMBER(SEARCH("mile",Table3[[#This Row],[Distance]])),ROUND(VALUE(SUBSTITUTE(Table3[[#This Row],[Distance]]," miles",""))*Lookups!$L$3,0),ROUND(VALUE(SUBSTITUTE(Table3[[#This Row],[Distance]]," meters",""))*Lookups!$L$4,0)) -> 40 | O4: 458 Brigade Road, Bengaluru, 560001 | P4: =TRIM(LEFT(Table3[[#This Row],[Shipping Address]],FIND(",",Table3[[#This Row],[Shipping Address]])-1)) -> 458 Brigade Road | Q4: =TRIM(MID(Table3[[#This Row],[Shipping Address]],FIND(",",Table3[[#This Row],[Shipping Address]])+1,FIND(",",Table3[[#This Row],[Shipping Address]],FIND(",",Table3[[#This Row],[Shipping Address]])+1)-FIND(",",Table3[[#This Row],[Shipping Address]])-1)) -> Bengaluru | R4: =TRIM(MID(Table3[[#This Row],[Shipping Address]],FIND(",",Table3[[#This Row],[Shipping Address]],FIND(",",Table3[[#This Row],[Shipping Address]])+1)+1,20)) -> 560001 | S4: IN | T4: =_xlfn.IFNA(_xlfn.XLOOKUP(Table3[[#This Row],[Country Code]],Lookups!$A$2:$A$5,Lookups!$B$2:$B$5),"CHECK CODE") -> India | U4: =_xlfn.IFNA(_xlfn.XLOOKUP(Table3[[#This Row],[Country Code]],Lookups!$A$2:$A$5,Lookups!$C$2:$C$5),"CHECK CODE") -> Asia | V4: ₹22,000 | W4: =_xlfn.IFNA(_xlfn.XLOOKUP(Table3[[#This Row],[Country Code]],Lookups!$A$2:$A$5,Lookups!$D$2:$D$5),"CHECK CODE") -> INR | X4: =VALUE(MID(Table3[[#This Row],[Unit Price]],2,50)) -> 22000 | Y4: =_xlfn.IFNA(_xlfn.XLOOKUP(Table3[[#This Row],[Country Code]],Lookups!$A$2:$A$5,Lookups!$E$2:$E$5),"") -> 109.882 | Z4: =Table3[[#This Row],[Unit Price (local)]]/Table3[[#This Row],[FX Rate (per EUR)]] -> 200.21478 | AA4: 200 | AB4: 10 | AC4: =ROUND(Table3[[#This Row],[Unit Price (EUR)]]*Table3[[#This Row],[Units Sold]],0) -> 40043 | AD4: =ROUND(Table3[[#This Row],[Gross Sales (EUR)]]*(1-Table3[[#This Row],[Discount (%)]]/100),0) -> 36039 | AE4: =_xlfn.IFNA(_xlfn.XLOOKUP(Table3[[#This Row],[Month]],Lookups!$N$2:$N$13,Lookups!$O$2:$O$13),"CHECK MONTH") -> 1 | AF4: =TEXT(Table3[[#This Row],[Month No]],"00")&" - "&Table3[[#This Row],[Month]] -> 01 - January | AG4: =_xlfn.IFNA(_xlfn.XLOOKUP(Table3[[#This Row],[Month]],Lookups!$N$2:$N$13,Lookups!$P$2:$P$13),"CHECK MONTH") -> Q1 | AH4: =Table3[[#This Row],[Gross Sales (EUR)]]-Table3[[#This Row],[Total Sales (EUR)]] -> 4004 | AI4: =DATE(Lookups!$O$15,Table3[[#This Row],[Month No]],1) -> 45658
A5: 4 | B5: Fang | C5: Liu | D5: =TRIM(Table3[[#This Row],[Rep Last Name]])&", "&TRIM(Table3[[#This Row],[Rep First Name]]) -> Liu, Fang | E5: January | F5: Electric Unicycle | G5: 15 mph | H5: =IF(Table3[[#This Row],[Min Speed (original, incomplete)]]="",_xlfn.IFNA(_xlfn.XLOOKUP(Table3[[#This Row],[Product Type]],Lookups!$G$2:$G$4,Lookups!$H$2:$H$4),"CHECK PRODUCT"),Table3[[#This Row],[Min Speed (original, incomplete)]]) -> 15 mph | I5: 30 mph | J5: 30 miles | K5: =ROUND(VALUE(SUBSTITUTE(Table3[[#This Row],[Min Speed (mph)]]," mph",""))*Lookups!$L$2,0) -> 24 | L5: =ROUND(VALUE(SUBSTITUTE(Table3[[#This Row],[Speed]]," mph",""))*Lookups!$L$2,0) -> 48 | M5: =Table3[[#This Row],[Min Speed (km/h)]]&" – "&Table3[[#This Row],[Max Speed (km/h)]]&" km/h" -> 24 – 48 km/h | N5: =IF(ISNUMBER(SEARCH("mile",Table3[[#This Row],[Distance]])),ROUND(VALUE(SUBSTITUTE(Table3[[#This Row],[Distance]]," miles",""))*Lookups!$L$3,0),ROUND(VALUE(SUBSTITUTE(Table3[[#This Row],[Distance]]," meters",""))*Lookups!$L$4,0)) -> 48 | O5: 99 Nanjing Road, Shanghai, 200001 | P5: =TRIM(LEFT(Table3[[#This Row],[Shipping Address]],FIND(",",Table3[[#This Row],[Shipping Address]])-1)) -> 99 Nanjing Road | Q5: =TRIM(MID(Table3[[#This Row],[Shipping Address]],FIND(",",Table3[[#This Row],[Shipping Address]])+1,FIND(",",Table3[[#This Row],[Shipping Address]],FIND(",",Table3[[#This Row],[Shipping Address]])+1)-FIND(",",Table3[[#This Row],[Shipping Address]])-1)) -> Shanghai | R5: =TRIM(MID(Table3[[#This Row],[Shipping Address]],FIND(",",Table3[[#This Row],[Shipping Address]],FIND(",",Table3[[#This Row],[Shipping Address]])+1)+1,20)) -> 200001 | S5: CN | T5: =_xlfn.IFNA(_xlfn.XLOOKUP(Table3[[#This Row],[Country Code]],Lookups!$A$2:$A$5,Lookups!$B$2:$B$5),"CHECK CODE") -> China | U5: =_xlfn.IFNA(_xlfn.XLOOKUP(Table3[[#This Row],[Country Code]],Lookups!$A$2:$A$5,Lookups!$C$2:$C$5),"CHECK CODE") -> Asia | V5: ¥5,000 | W5: =_xlfn.IFNA(_xlfn.XLOOKUP(Table3[[#This Row],[Country Code]],Lookups!$A$2:$A$5,Lookups!$D$2:$D$5),"CHECK CODE") -> CNY | X5: =VALUE(MID(Table3[[#This Row],[Unit Price]],2,50)) -> 5000 | Y5: =_xlfn.IFNA(_xlfn.XLOOKUP(Table3[[#This Row],[Country Code]],Lookups!$A$2:$A$5,Lookups!$E$2:$E$5),"") -> 7.7255 | Z5: =Table3[[#This Row],[Unit Price (local)]]/Table3[[#This Row],[FX Rate (per EUR)]] -> 647.2073 | AA5: 500 | AB5: 10 | AC5: =ROUND(Table3[[#This Row],[Unit Price (EUR)]]*Table3[[#This Row],[Units Sold]],0) -> 323604 | AD5: =ROUND(Table3[[#This Row],[Gross Sales (EUR)]]*(1-Table3[[#This Row],[Discount (%)]]/100),0) -> 291244 | AE5: =_xlfn.IFNA(_xlfn.XLOOKUP(Table3[[#This Row],[Month]],Lookups!$N$2:$N$13,Lookups!$O$2:$O$13),"CHECK MONTH") -> 1 | AF5: =TEXT(Table3[[#This Row],[Month No]],"00")&" - "&Table3[[#This Row],[Month]] -> 01 - January | AG5: =_xlfn.IFNA(_xlfn.XLOOKUP(Table3[[#This Row],[Month]],Lookups!$N$2:$N$13,Lookups!$P$2:$P$13),"CHECK MONTH") -> Q1 | AH5: =Table3[[#This Row],[Gross Sales (EUR)]]-Table3[[#This Row],[Total Sales (EUR)]] -> 32360 | AI5: =DATE(Lookups!$O$15,Table3[[#This Row],[Month No]],1) -> 45658
A6: 5 | B6: Fang | C6: Liu | D6: =TRIM(Table3[[#This Row],[Rep Last Name]])&", "&TRIM(Table3[[#This Row],[Rep First Name]]) -> Liu, Fang | E6: January | F6: Electric Scooter | G6: 20 mph | H6: =IF(Table3[[#This Row],[Min Speed (original, incomplete)]]="",_xlfn.IFNA(_xlfn.XLOOKUP(Table3[[#This Row],[Product Type]],Lookups!$G$2:$G$4,Lookups!$H$2:$H$4),"CHECK PRODUCT"),Table3[[#This Row],[Min Speed (original, incomplete)]]) -> 20 mph | I6: 35 mph | J6: 40 miles | K6: =ROUND(VALUE(SUBSTITUTE(Table3[[#This Row],[Min Speed (mph)]]," mph",""))*Lookups!$L$2,0) -> 32 | L6: =ROUND(VALUE(SUBSTITUTE(Table3[[#This Row],[Speed]]," mph",""))*Lookups!$L$2,0) -> 56 | M6: =Table3[[#This Row],[Min Speed (km/h)]]&" – "&Table3[[#This Row],[Max Speed (km/h)]]&" km/h" -> 32 – 56 km/h | N6: =IF(ISNUMBER(SEARCH("mile",Table3[[#This Row],[Distance]])),ROUND(VALUE(SUBSTITUTE(Table3[[#This Row],[Distance]]," miles",""))*Lookups!$L$3,0),ROUND(VALUE(SUBSTITUTE(Table3[[#This Row],[Distance]]," meters",""))*Lookups!$L$4,0)) -> 64 | O6: 100 Nanjing Road, Shanghai, 200001 | P6: =TRIM(LEFT(Table3[[#This Row],[Shipping Address]],FIND(",",Table3[[#This Row],[Shipping Address]])-1)) -> 100 Nanjing Road | Q6: =TRIM(MID(Table3[[#This Row],[Shipping Address]],FIND(",",Table3[[#This Row],[Shipping Address]])+1,FIND(",",Table3[[#This Row],[Shipping Address]],FIND(",",Table3[[#This Row],[Shipping Address]])+1)-FIND(",",Table3[[#This Row],[Shipping Address]])-1)) -> Shanghai | R6: =TRIM(MID(Table3[[#This Row],[Shipping Address]],FIND(",",Table3[[#This Row],[Shipping Address]],FIND(",",Table3[[#This Row],[Shipping Address]])+1)+1,20)) -> 200001 | S6: CN | T6: =_xlfn.IFNA(_xlfn.XLOOKUP(Table3[[#This Row],[Country Code]],Lookups!$A$2:$A$5,Lookups!$B$2:$B$5),"CHECK CODE") -> China | U6: =_xlfn.IFNA(_xlfn.XLOOKUP(Table3[[#This Row],[Country Code]],Lookups!$A$2:$A$5,Lookups!$C$2:$C$5),"CHECK CODE") -> Asia | V6: ¥3,500 | W6: =_xlfn.IFNA(_xlfn.XLOOKUP(Table3[[#This Row],[Country Code]],Lookups!$A$2:$A$5,Lookups!$D$2:$D$5),"CHECK CODE") -> CNY | X6: =VALUE(MID(Table3[[#This Row],[Unit Price]],2,50)) -> 3500 | Y6: =_xlfn.IFNA(_xlfn.XLOOKUP(Table3[[#This Row],[Country Code]],Lookups!$A$2:$A$5,Lookups!$E$2:$E$5),"") -> 7.7255 | Z6: =Table3[[#This Row],[Unit Price (local)]]/Table3[[#This Row],[FX Rate (per EUR)]] -> 453.04511 | AA6: 1000 | AB6: 10 | AC6: =ROUND(Table3[[#This Row],[Unit Price (EUR)]]*Table3[[#This Row],[Units Sold]],0) -> 453045 | AD6: =ROUND(Table3[[#This Row],[Gross Sales (EUR)]]*(1-Table3[[#This Row],[Discount (%)]]/100),0) -> 407741 | AE6: =_xlfn.IFNA(_xlfn.XLOOKUP(Table3[[#This Row],[Month]],Lookups!$N$2:$N$13,Lookups!$O$2:$O$13),"CHECK MONTH") -> 1 | AF6: =TEXT(Table3[[#This Row],[Month No]],"00")&" - "&Table3[[#This Row],[Month]] -> 01 - January | AG6: =_xlfn.IFNA(_xlfn.XLOOKUP(Table3[[#This Row],[Month]],Lookups!$N$2:$N$13,Lookups!$P$2:$P$13),"CHECK MONTH") -> Q1 | AH6: =Table3[[#This Row],[Gross Sales (EUR)]]-Table3[[#This Row],[Total Sales (EUR)]] -> 45304 | AI6: =DATE(Lookups!$O$15,Table3[[#This Row],[Month No]],1) -> 45658
A7: 6 | B7: Fang | C7: Liu | D7: =TRIM(Table3[[#This Row],[Rep Last Name]])&", "&TRIM(Table3[[#This Row],[Rep First Name]]) -> Liu, Fang | E7: January | F7: Electric Skateboard | H7: =IF(Table3[[#This Row],[Min Speed (original, incomplete)]]="",_xlfn.IFNA(_xlfn.XLOOKUP(Table3[[#This Row],[Product Type]],Lookups!$G$2:$G$4,Lookups!$H$2:$H$4),"CHECK PRODUCT"),Table3[[#This Row],[Min Speed (original, incomplete)]]) -> 18 mph | I7: 28 mph | J7: 40,230 meters | K7: =ROUND(VALUE(SUBSTITUTE(Table3[[#This Row],[Min Speed (mph)]]," mph",""))*Lookups!$L$2,0) -> 29 | L7: =ROUND(VALUE(SUBSTITUTE(Table3[[#This Row],[Speed]]," mph",""))*Lookups!$L$2,0) -> 45 | M7: =Table3[[#This Row],[Min Speed (km/h)]]&" – "&Table3[[#This Row],[Max Speed (km/h)]]&" km/h" -> 29 – 45 km/h | N7: =IF(ISNUMBER(SEARCH("mile",Table3[[#This Row],[Distance]])),ROUND(VALUE(SUBSTITUTE(Table3[[#This Row],[Distance]]," miles",""))*Lookups!$L$3,0),ROUND(VALUE(SUBSTITUTE(Table3[[#This Row],[Distance]]," meters",""))*Lookups!$L$4,0)) -> 40 | O7: 101 Nanjing Road, Shanghai, 200001 | P7: =TRIM(LEFT(Table3[[#This Row],[Shipping Address]],FIND(",",Table3[[#This Row],[Shipping Address]])-1)) -> 101 Nanjing Road | Q7: =TRIM(MID(Table3[[#This Row],[Shipping Address]],FIND(",",Table3[[#This Row],[Shipping Address]])+1,FIND(",",Table3[[#This Row],[Shipping Address]],FIND(",",Table3[[#This Row],[Shipping Address]])+1)-FIND(",",Table3[[#This Row],[Shipping Address]])-1)) -> Shanghai | R7: =TRIM(MID(Table3[[#This Row],[Shipping Address]],FIND(",",Table3[[#This Row],[Shipping Address]],FIND(",",Table3[[#This Row],[Shipping Address]])+1)+1,20)) -> 200001 | S7: CN | T7: =_xlfn.IFNA(_xlfn.XLOOKUP(Table3[[#This Row],[Country Code]],Lookups!$A$2:$A$5,Lookups!$B$2:$B$5),"CHECK CODE") -> China | U7: =_xlfn.IFNA(_xlfn.XLOOKUP(Table3[[#This Row],[Country Code]],Lookups!$A$2:$A$5,Lookups!$C$2:$C$5),"CHECK CODE") -> Asia | V7: ¥4,200 | W7: =_xlfn.IFNA(_xlfn.XLOOKUP(Table3[[#This Row],[Country Code]],Lookups!$A$2:$A$5,Lookups!$D$2:$D$5),"CHECK CODE") -> CNY | X7: =VALUE(MID(Table3[[#This Row],[Unit Price]],2,50)) -> 4200 | Y7: =_xlfn.IFNA(_xlfn.XLOOKUP(Table3[[#This Row],[Country Code]],Lookups!$A$2:$A$5,Lookups!$E$2:$E$5),"") -> 7.7255 | Z7: =Table3[[#This Row],[Unit Price (local)]]/Table3[[#This Row],[FX Rate (per EUR)]] -> 543.65413 | AA7: 800 | AB7: 10 | AC7: =ROUND(Table3[[#This Row],[Unit Price (EUR)]]*Table3[[#This Row],[Units Sold]],0) -> 434923 | AD7: =ROUND(Table3[[#This Row],[Gross Sales (EUR)]]*(1-Table3[[#This Row],[Discount (%)]]/100),0) -> 391431 | AE7: =_xlfn.IFNA(_xlfn.XLOOKUP(Table3[[#This Row],[Month]],Lookups!$N$2:$N$13,Lookups!$O$2:$O$13),"CHECK MONTH") -> 1 | AF7: =TEXT(Table3[[#This Row],[Month No]],"00")&" - "&Table3[[#This Row],[Month]] -> 01 - January | AG7: =_xlfn.IFNA(_xlfn.XLOOKUP(Table3[[#This Row],[Month]],Lookups!$N$2:$N$13,Lookups!$P$2:$P$13),"CHECK MONTH") -> Q1 | AH7: =Table3[[#This Row],[Gross Sales (EUR)]]-Table3[[#This Row],[Total Sales (EUR)]] -> 43492 | AI7: =DATE(Lookups!$O$15,Table3[[#This Row],[Month No]],1) -> 45658
A8: 7 | B8: Jonas | C8: Fischer | D8: =TRIM(Table3[[#This Row],[Rep Last Name]])&", "&TRIM(Table3[[#This Row],[Rep First Name]]) -> Fischer, Jonas | E8: January | F8: Electric Unicycle | G8: 15 mph | H8: =IF(Table3[[#This Row],[Min Speed (original, incomplete)]]="",_xlfn.IFNA(_xlfn.XLOOKUP(Table3[[#This Row],[Product Type]],Lookups!$G$2:$G$4,Lookups!$H$2:$H$4),"CHECK PRODUCT"),Table3[[#This Row],[Min Speed (original, incomplete)]]) -> 15 mph | I8: 30 mph | J8: 48,280 meters | K8: =ROUND(VALUE(SUBSTITUTE(Table3[[#This Row],[Min Speed (mph)]]," mph",""))*Lookups!$L$2,0) -> 24 | L8: =ROUND(VALUE(SUBSTITUTE(Table3[[#This Row],[Speed]]," mph",""))*Lookups!$L$2,0) -> 48 | M8: =Table3[[#This Row],[Min Speed (km/h)]]&" – "&Table3[[#This Row],[Max Speed (km/h)]]&" km/h" -> 24 – 48 km/h | N8: =IF(ISNUMBER(SEARCH("mile",Table3[[#This Row],[Distance]])),ROUND(VALUE(SUBSTITUTE(Table3[[#This Row],[Distance]]," miles",""))*Lookups!$L$3,0),ROUND(VALUE(SUBSTITUTE(Table3[[#This Row],[Distance]]," meters",""))*Lookups!$L$4,0)) -> 48 | O8: 303 Ringstraße, Hamburg, 20095 | P8: =TRIM(LEFT(Table3[[#This Row],[Shipping Address]],FIND(",",Table3[[#This Row],[Shipping Address]])-1)) -> 303 Ringstraße | Q8: =TRIM(MID(Table3[[#This Row],[Shipping Address]],FIND(",",Table3[[#This Row],[Shipping Address]])+1,FIND(",",Table3[[#This Row],[Shipping Address]],FIND(",",Table3[[#This Row],[Shipping Address]])+1)-FIND(",",Table3[[#This Row],[Shipping Address]])-1)) -> Hamburg | R8: =TRIM(MID(Table3[[#This Row],[Shipping Address]],FIND(",",Table3[[#This Row],[Shipping Address]],FIND(",",Table3[[#This Row],[Shipping Address]])+1)+1,20)) -> 20095 | S8: DE | T8: =_xlfn.IFNA(_xlfn.XLOOKUP(Table3[[#This Row],[Country Code]],Lookups!$A$2:$A$5,Lookups!$B$2:$B$5),"CHECK CODE") -> Germany | U8: =_xlfn.IFNA(_xlfn.XLOOKUP(Table3[[#This Row],[Country Code]],Lookups!$A$2:$A$5,Lookups!$C$2:$C$5),"CHECK CODE") -> Europe | V8: €1000 | W8: =_xlfn.IFNA(_xlfn.XLOOKUP(Table3[[#This Row],[Country Code]],Lookups!$A$2:$A$5,Lookups!$D$2:$D$5),"CHECK CODE") -> EUR | X8: =VALUE(MID(Table3[[#This Row],[Unit Price]],2,50)) -> 1000 | Y8: =_xlfn.IFNA(_xlfn.XLOOKUP(Table3[[#This Row],[Country Code]],Lookups!$A$2:$A$5,Lookups!$E$2:$E$5),"") -> 1 | Z8: =Table3[[#This Row],[Unit Price (local)]]/Table3[[#This Row],[FX Rate (per EUR)]] -> 1000 | AA8: 120 | AB8: 10 | AC8: =ROUND(Table3[[#This Row],[Unit Price (EUR)]]*Table3[[#This Row],[Units Sold]],0) -> 120000 | AD8: =ROUND(Table3[[#This Row],[Gross Sales (EUR)]]*(1-Table3[[#This Row],[Discount (%)]]/100),0) -> 108000 | AE8: =_xlfn.IFNA(_xlfn.XLOOKUP(Table3[[#This Row],[Month]],Lookups!$N$2:$N$13,Lookups!$O$2:$O$13),"CHECK MONTH") -> 1 | AF8: =TEXT(Table3[[#This Row],[Month No]],"00")&" - "&Table3[[#This Row],[Month]] -> 01 - January | AG8: =_xlfn.IFNA(_xlfn.XLOOKUP(Table3[[#This Row],[Month]],Lookups!$N$2:$N$13,Lookups!$P$2:$P$13),"CHECK MONTH") -> Q1 | AH8: =Table3[[#This Row],[Gross Sales (EUR)]]-Table3[[#This Row],[Total Sales (EUR)]] -> 12000 | AI8: =DATE(Lookups!$O$15,Table3[[#This Row],[Month No]],1) -> 45658
A9: 8 | B9: Jonas | C9: Fischer | D9: =TRIM(Table3[[#This Row],[Rep Last Name]])&", "&TRIM(Table3[[#This Row],[Rep First Name]]) -> Fischer, Jonas | E9: January | F9: Electric Scooter | G9: 20 mph | H9: =IF(Table3[[#This Row],[Min Speed (original, incomplete)]]="",_xlfn.IFNA(_xlfn.XLOOKUP(Table3[[#This Row],[Product Type]],Lookups!$G$2:$G$4,Lookups!$H$2:$H$4),"CHECK PRODUCT"),Table3[[#This Row],[Min Speed (original, incomplete)]]) -> 20 mph | I9: 35 mph | J9: 40 miles | K9: =ROUND(VALUE(SUBSTITUTE(Table3[[#This Row],[Min Speed (mph)]]," mph",""))*Lookups!$L$2,0) -> 32 | L9: =ROUND(VALUE(SUBSTITUTE(Table3[[#This Row],[Speed]]," mph",""))*Lookups!$L$2,0) -> 56 | M9: =Table3[[#This Row],[Min Speed (km/h)]]&" – "&Table3[[#This Row],[Max Speed (km/h)]]&" km/h" -> 32 – 56 km/h | N9: =IF(ISNUMBER(SEARCH("mile",Table3[[#This Row],[Distance]])),ROUND(VALUE(SUBSTITUTE(Table3[[#This Row],[Distance]]," miles",""))*Lookups!$L$3,0),ROUND(VALUE(SUBSTITUTE(Table3[[#This Row],[Distance]]," meters",""))*Lookups!$L$4,0)) -> 64 | O9: 304 Ringstraße, Hamburg, 20095 | P9: =TRIM(LEFT(Table3[[#This Row],[Shipping Address]],FIND(",",Table3[[#This Row],[Shipping Address]])-1)) -> 304 Ringstraße | Q9: =TRIM(MID(Table3[[#This Row],[Shipping Address]],FIND(",",Table3[[#This Row],[Shipping Address]])+1,FIND(",",Table3[[#This Row],[Shipping Address]],FIND(",",Table3[[#This Row],[Shipping Address]])+1)-FIND(",",Table3[[#This Row],[Shipping Address]])-1)) -> Hamburg | R9: =TRIM(MID(Table3[[#This Row],[Shipping Address]],FIND(",",Table3[[#This Row],[Shipping Address]],FIND(",",Table3[[#This Row],[Shipping Address]])+1)+1,20)) -> 20095 | S9: DE | T9: =_xlfn.IFNA(_xlfn.XLOOKUP(Table3[[#This Row],[Country Code]],Lookups!$A$2:$A$5,Lookups!$B$2:$B$5),"CHECK CODE") -> Germany | U9: =_xlfn.IFNA(_xlfn.XLOOKUP(Table3[[#This Row],[Country Code]],Lookups!$A$2:$A$5,Lookups!$C$2:$C$5),"CHECK CODE") -> Europe | V9: €800 | W9: =_xlfn.IFNA(_xlfn.XLOOKUP(Table3[[#This Row],[Country Code]],Lookups!$A$2:$A$5,Lookups!$D$2:$D$5),"CHECK CODE") -> EUR | X9: =VALUE(MID(Table3[[#This Row],[Unit Price]],2,50)) -> 800 | Y9: =_xlfn.IFNA(_xlfn.XLOOKUP(Table3[[#This Row],[Country Code]],Lookups!$A$2:$A$5,Lookups!$E$2:$E$5),"") -> 1 | Z9: =Table3[[#This Row],[Unit Price (local)]]/Table3[[#This Row],[FX Rate (per EUR)]] -> 800 | AA9: 200 | AB9: 10 | AC9: =ROUND(Table3[[#This Row],[Unit Price (EUR)]]*Table3[[#This Row],[Units Sold]],0) -> 160000 | AD9: =ROUND(Table3[[#This Row],[Gross Sales (EUR)]]*(1-Table3[[#This Row],[Discount (%)]]/100),0) -> 144000 | AE9: =_xlfn.IFNA(_xlfn.XLOOKUP(Table3[[#This Row],[Month]],Lookups!$N$2:$N$13,Lookups!$O$2:$O$13),"CHECK MONTH") -> 1 | AF9: =TEXT(Table3[[#This Row],[Month No]],"00")&" - "&Table3[[#This Row],[Month]] -> 01 - January | AG9: =_xlfn.IFNA(_xlfn.XLOOKUP(Table3[[#This Row],[Month]],Lookups!$N$2:$N$13,Lookups!$P$2:$P$13),"CHECK MONTH") -> Q1 | AH9: =Table3[[#This Row],[Gross Sales (EUR)]]-Table3[[#This Row],[Total Sales (EUR)]] -> 16000 | AI9: =DATE(Lookups!$O$15,Table3[[#This Row],[Month No]],1) -> 45658
A10: 9 | B10: Jonas | C10: Fischer | D10: =TRIM(Table3[[#This Row],[Rep Last Name]])&", "&TRIM(Table3[[#This Row],[Rep First Name]]) -> Fischer, Jonas | E10: January | F10: Electric Skateboard | G10: 18 mph | H10: =IF(Table3[[#This Row],[Min Speed (original, incomplete)]]="",_xlfn.IFNA(_xlfn.XLOOKUP(Table3[[#This Row],[Product Type]],Lookups!$G$2:$G$4,Lookups!$H$2:$H$4),"CHECK PRODUCT"),Table3[[#This Row],[Min Speed (original, incomplete)]]) -> 18 mph | I10: 28 mph | J10: 25 miles | K10: =ROUND(VALUE(SUBSTITUTE(Table3[[#This Row],[Min Speed (mph)]]," mph",""))*Lookups!$L$2,0) -> 29 | L10: =ROUND(VALUE(SUBSTITUTE(Table3[[#This Row],[Speed]]," mph",""))*Lookups!$L$2,0) -> 45 | M10: =Table3[[#This Row],[Min Speed (km/h)]]&" – "&Table3[[#This Row],[Max Speed (km/h)]]&" km/h" -> 29 – 45 km/h | N10: =IF(ISNUMBER(SEARCH("mile",Table3[[#This Row],[Distance]])),ROUND(VALUE(SUBSTITUTE(Table3[[#This Row],[Distance]]," miles",""))*Lookups!$L$3,0),ROUND(VALUE(SUBSTITUTE(Table3[[#This Row],[Distance]]," meters",""))*Lookups!$L$4,0)) -> 40 | O10: 305 Ringstraße, Hamburg, 20095 | P10: =TRIM(LEFT(Table3[[#This Row],[Shipping Address]],FIND(",",Table3[[#This Row],[Shipping Address]])-1)) -> 305 Ringstraße | Q10: =TRIM(MID(Table3[[#This Row],[Shipping Address]],FIND(",",Table3[[#This Row],[Shipping Address]])+1,FIND(",",Table3[[#This Row],[Shipping Address]],FIND(",",Table3[[#This Row],[Shipping Address]])+1)-FIND(",",Table3[[#This Row],[Shipping Address]])-1)) -> Hamburg | R10: =TRIM(MID(Table3[[#This Row],[Shipping Address]],FIND(",",Table3[[#This Row],[Shipping Address]],FIND(",",Table3[[#This Row],[Shipping Address]])+1)+1,20)) -> 20095 | S10: DE | T10: =_xlfn.IFNA(_xlfn.XLOOKUP(Table3[[#This Row],[Country Code]],Lookups!$A$2:$A$5,Lookups!$B$2:$B$5),"CHECK CODE") -> Germany | U10: =_xlfn.IFNA(_xlfn.XLOOKUP(Table3[[#This Row],[Country Code]],Lookups!$A$2:$A$5,Lookups!$C$2:$C$5),"CHECK CODE") -> Europe | V10: €950 | W10: =_xlfn.IFNA(_xlfn.XLOOKUP(Table3[[#This Row],[Country Code]],Lookups!$A$2:$A$5,Lookups!$D$2:$D$5),"CHECK CODE") -> EUR | X10: =VALUE(MID(Table3[[#This Row],[Unit Price]],2,50)) -> 950 | Y10: =_xlfn.IFNA(_xlfn.XLOOKUP(Table3[[#This Row],[Country Code]],Lookups!$A$2:$A$5,Lookups!$E$2:$E$5),"") -> 1 | Z10: =Table3[[#This Row],[Unit Price (local)]]/Table3[[#This Row],[FX Rate (per EUR)]] -> 950 | AA10: 150 | AB10: 10 | AC10: =ROUND(Table3[[#This Row],[Unit Price (EUR)]]*Table3[[#This Row],[Units Sold]],0) -> 142500 | AD10: =ROUND(Table3[[#This Row],[Gross Sales (EUR)]]*(1-Table3[[#This Row],[Discount (%)]]/100),0) -> 128250 | AE10: =_xlfn.IFNA(_xlfn.XLOOKUP(Table3[[#This Row],[Month]],Lookups!$N$2:$N$13,Lookups!$O$2:$O$13),"CHECK MONTH") -> 1 | AF10: =TEXT(Table3[[#This Row],[Month No]],"00")&" - "&Table3[[#This Row],[Month]] -> 01 - January | AG10: =_xlfn.IFNA(_xlfn.XLOOKUP(Table3[[#This Row],[Month]],Lookups!$N$2:$N$13,Lookups!$P$2:$P$13),"CHECK MONTH") -> Q1 | AH10: =Table3[[#This Row],[Gross Sales (EUR)]]-Table3[[#This Row],[Total Sales (EUR)]] -> 14250 | AI10: =DATE(Lookups!$O$15,Table3[[#This Row],[Month No]],1) -> 45658
A11: 10 | B11: Théo | C11: Bernard | D11: =TRIM(Table3[[#This Row],[Rep Last Name]])&", "&TRIM(Table3[[#This Row],[Rep First Name]]) -> Bernard, Théo | E11: January | F11: Electric Unicycle | G11: 15 mph | H11: =IF(Table3[[#This Row],[Min Speed (original, incomplete)]]="",_xlfn.IFNA(_xlfn.XLOOKUP(Table3[[#This Row],[Product Type]],Lookups!$G$2:$G$4,Lookups!$H$2:$H$4),"CHECK PRODUCT"),Table3[[#This Row],[Min Speed (original, incomplete)]]) -> 15 mph | I11: 30 mph | J11: 30 miles | K11: =ROUND(VALUE(SUBSTITUTE(Table3[[#This Row],[Min Speed (mph)]]," mph",""))*Lookups!$L$2,0) -> 24 | L11: =ROUND(VALUE(SUBSTITUTE(Table3[[#This Row],[Speed]]," mph",""))*Lookups!$L$2,0) -> 48 | M11: =Table3[[#This Row],[Min Speed (km/h)]]&" – "&Table3[[#This Row],[Max Speed (km/h)]]&" km/h" -> 24 – 48 km/h | N11: =IF(ISNUMBER(SEARCH("mile",Table3[[#This Row],[Distance]])),ROUND(VALUE(SUBSTITUTE(Table3[[#This Row],[Distance]]," miles",""))*Lookups!$L$3,0),ROUND(VALUE(SUBSTITUTE(Table3[[#This Row],[Distance]]," meters",""))*Lookups!$L$4,0)) -> 48 | O11: 56 Boulevard Saint-Germain, Paris, 75005 | P11: =TRIM(LEFT(Table3[[#This Row],[Shipping Address]],FIND(",",Table3[[#This Row],[Shipping Address]])-1)) -> 56 Boulevard Saint-Germain | Q11: =TRIM(MID(Table3[[#This Row],[Shipping Address]],FIND(",",Table3[[#This Row],[Shipping Address]])+1,FIND(",",Table3[[#This Row],[Shipping Address]],FIND(",",Table3[[#This Row],[Shipping Address]])+1)-FIND(",",Table3[[#This Row],[Shipping Address]])-1)) -> Paris | R11: =TRIM(MID(Table3[[#This Row],[Shipping Address]],FIND(",",Table3[[#This Row],[Shipping Address]],FIND(",",Table3[[#This Row],[Shipping Address]])+1)+1,20)) -> 75005 | S11: FR | T11: =_xlfn.IFNA(_xlfn.XLOOKUP(Table3[[#This Row],[Country Code]],Lookups!$A$2:$A$5,Lookups!$B$2:$B$5),"CHECK CODE") -> France | U11: =_xlfn.IFNA(_xlfn.XLOOKUP(Table3[[#This Row],[Country Code]],Lookups!$A$2:$A$5,Lookups!$C$2:$C$5),"CHECK CODE") -> Europe | V11: €1100 | W11: =_xlfn.IFNA(_xlfn.XLOOKUP(Table3[[#This Row],[Country Code]],Lookups!$A$2:$A$5,Lookups!$D$2:$D$5),"CHECK CODE") -> EUR | X11: =VALUE(MID(Table3[[#This Row],[Unit Price]],2,50)) -> 1100 | Y11: =_xlfn.IFNA(_xlfn.XLOOKUP(Table3[[#This Row],[Country Code]],Lookups!$A$2:$A$5,Lookups!$E$2:$E$5),"") -> 1 | Z11: =Table3[[#This Row],[Unit Price (local)]]/Table3[[#This Row],[FX Rate (per EUR)]] -> 1100 | AA11: 100 | AB11: 10 | AC11: =ROUND(Table3[[#This Row],[Unit Price (EUR)]]*Table3[[#This Row],[Units Sold]],0) -> 110000 | AD11: =ROUND(Table3[[#This Row],[Gross Sales (EUR)]]*(1-Table3[[#This Row],[Discount (%)]]/100),0) -> 99000 | AE11: =_xlfn.IFNA(_xlfn.XLOOKUP(Table3[[#This Row],[Month]],Lookups!$N$2:$N$13,Lookups!$O$2:$O$13),"CHECK MONTH") -> 1 | AF11: =TEXT(Table3[[#This Row],[Month No]],"00")&" - "&Table3[[#This Row],[Month]] -> 01 - January | AG11: =_xlfn.IFNA(_xlfn.XLOOKUP(Table3[[#This Row],[Month]],Lookups!$N$2:$N$13,Lookups!$P$2:$P$13),"CHECK MONTH") -> Q1 | AH11: =Table3[[#This Row],[Gross Sales (EUR)]]-Table3[[#This Row],[Total Sales (EUR)]] -> 11000 | AI11: =DATE(Lookups!$O$15,Table3[[#This Row],[Month No]],1) -> 45658
A12: 11 | B12: Théo | C12: Bernard | D12: =TRIM(Table3[[#This Row],[Rep Last Name]])&", "&TRIM(Table3[[#This Row],[Rep First Name]]) -> Bernard, Théo | E12: January | F12: Electric Scooter | G12: 20 mph | H12: =IF(Table3[[#This Row],[Min Speed (original, incomplete)]]="",_xlfn.IFNA(_xlfn.XLOOKUP(Table3[[#This Row],[Product Type]],Lookups!$G$2:$G$4,Lookups!$H$2:$H$4),"CHECK PRODUCT"),Table3[[#This Row],[Min Speed (original, incomplete)]]) -> 20 mph | I12: 35 mph | J12: 64,370 meters | K12: =ROUND(VALUE(SUBSTITUTE(Table3[[#This Row],[Min Speed (mph)]]," mph",""))*Lookups!$L$2,0) -> 32 | L12: =ROUND(VALUE(SUBSTITUTE(Table3[[#This Row],[Speed]]," mph",""))*Lookups!$L$2,0) -> 56 | M12: =Table3[[#This Row],[Min Speed (km/h)]]&" – "&Table3[[#This Row],[Max Speed (km/h)]]&" km/h" -> 32 – 56 km/h | N12: =IF(ISNUMBER(SEARCH("mile",Table3[[#This Row],[Distance]])),ROUND(VALUE(SUBSTITUTE(Table3[[#This Row],[Distance]]," miles",""))*Lookups!$L$3,0),ROUND(VALUE(SUBSTITUTE(Table3[[#This Row],[Distance]]," meters",""))*Lookups!$L$4,0)) -> 64 | O12: 57 Boulevard Saint-Germain, Paris, 75005 | P12: =TRIM(LEFT(Table3[[#This Row],[Shipping Address]],FIND(",",Table3[[#This Row],[Shipping Address]])-1)) -> 57 Boulevard Saint-Germain | Q12: =TRIM(MID(Table3[[#This Row],[Shipping Address]],FIND(",",Table3[[#This Row],[Shipping Address]])+1,FIND(",",Table3[[#This Row],[Shipping Address]],FIND(",",Table3[[#This Row],[Shipping Address]])+1)-FIND(",",Table3[[#This Row],[Shipping Address]])-1)) -> Paris | R12: =TRIM(MID(Table3[[#This Row],[Shipping Address]],FIND(",",Table3[[#This Row],[Shipping Address]],FIND(",",Table3[[#This Row],[Shipping Address]])+1)+1,20)) -> 75005 | S12: FR | T12: =_xlfn.IFNA(_xlfn.XLOOKUP(Table3[[#This Row],[Country Code]],Lookups!$A$2:$A$5,Lookups!$B$2:$B$5),"CHECK CODE") -> France | U12: =_xlfn.IFNA(_xlfn.XLOOKUP(Table3[[#This Row],[Country Code]],Lookups!$A$2:$A$5,Lookups!$C$2:$C$5),"CHECK CODE") -> Europe | V12: €900 | W12: =_xlfn.IFNA(_xlfn.XLOOKUP(Table3[[#This Row],[Country Code]],Lookups!$A$2:$A$5,Lookups!$D$2:$D$5),"CHECK CODE") -> EUR | X12: =VALUE(MID(Table3[[#This Row],[Unit Price]],2,50)) -> 900 | Y12: =_xlfn.IFNA(_xlfn.XLOOKUP(Table3[[#This Row],[Country Code]],Lookups!$A$2:$A$5,Lookups!$E$2:$E$5),"") -> 1 | Z12: =Table3[[#This Row],[Unit Price (local)]]/Table3[[#This Row],[FX Rate (per EUR)]] -> 900 | AA12: 250 | AB12: 10 | AC12: =ROUND(Table3[[#This Row],[Unit Price (EUR)]]*Table3[[#This Row],[Units Sold]],0) -> 225000 | AD12: =ROUND(Table3[[#This Row],[Gross Sales (EUR)]]*(1-Table3[[#This Row],[Discount (%)]]/100),0) -> 202500 | AE12: =_xlfn.IFNA(_xlfn.XLOOKUP(Table3[[#This Row],[Month]],Lookups!$N$2:$N$13,Lookups!$O$2:$O$13),"CHECK MONTH") -> 1 | AF12: =TEXT(Table3[[#This Row],[Month No]],"00")&" - "&Table3[[#This Row],[Month]] -> 01 - January | AG12: =_xlfn.IFNA(_xlfn.XLOOKUP(Table3[[#This Row],[Month]],Lookups!$N$2:$N$13,Lookups!$P$2:$P$13),"CHECK MONTH") -> Q1 | AH12: =Table3[[#This Row],[Gross Sales (EUR)]]-Table3[[#This Row],[Total Sales (EUR)]] -> 22500 | AI12: =DATE(Lookups!$O$15,Table3[[#This Row],[Month No]],1) -> 45658
A13: 12 | B13: Théo | C13: Bernard | D13: =TRIM(Table3[[#This Row],[Rep Last Name]])&", "&TRIM(Table3[[#This Row],[Rep First Name]]) -> Bernard, Théo | E13: January | F13: Electric Skateboard | G13: 18 mph | H13: =IF(Table3[[#This Row],[Min Speed (original, incomplete)]]="",_xlfn.IFNA(_xlfn.XLOOKUP(Table3[[#This Row],[Product Type]],Lookups!$G$2:$G$4,Lookups!$H$2:$H$4),"CHECK PRODUCT"),Table3[[#This Row],[Min Speed (original, incomplete)]]) -> 18 mph | I13: 28 mph | J13: 25 miles | K13: =ROUND(VALUE(SUBSTITUTE(Table3[[#This Row],[Min Speed (mph)]]," mph",""))*Lookups!$L$2,0) -> 29 | L13: =ROUND(VALUE(SUBSTITUTE(Table3[[#This Row],[Speed]]," mph",""))*Lookups!$L$2,0) -> 45 | M13: =Table3[[#This Row],[Min Speed (km/h)]]&" – "&Table3[[#This Row],[Max Speed (km/h)]]&" km/h" -> 29 – 45 km/h | N13: =IF(ISNUMBER(SEARCH("mile",Table3[[#This Row],[Distance]])),ROUND(VALUE(SUBSTITUTE(Table3[[#This Row],[Distance]]," miles",""))*Lookups!$L$3,0),ROUND(VALUE(SUBSTITUTE(Table3[[#This Row],[Distance]]," meters",""))*Lookups!$L$4,0)) -> 40 | O13: 58 Boulevard Saint-Germain, Paris, 75005 | P13: =TRIM(LEFT(Table3[[#This Row],[Shipping Address]],FIND(",",Table3[[#This Row],[Shipping Address]])-1)) -> 58 Boulevard Saint-Germain | Q13: =TRIM(MID(Table3[[#This Row],[Shipping Address]],FIND(",",Table3[[#This Row],[Shipping Address]])+1,FIND(",",Table3[[#This Row],[Shipping Address]],FIND(",",Table3[[#This Row],[Shipping Address]])+1)-FIND(",",Table3[[#This Row],[Shipping Address]])-1)) -> Paris | R13: =TRIM(MID(Table3[[#This Row],[Shipping Address]],FIND(",",Table3[[#This Row],[Shipping Address]],FIND(",",Table3[[#This Row],[Shipping Address]])+1)+1,20)) -> 75005 | S13: FR | T13: =_xlfn.IFNA(_xlfn.XLOOKUP(Table3[[#This Row],[Country Code]],Lookups!$A$2:$A$5,Lookups!$B$2:$B$5),"CHECK CODE") -> France | U13: =_xlfn.IFNA(_xlfn.XLOOKUP(Table3[[#This Row],[Country Code]],Lookups!$A$2:$A$5,Lookups!$C$2:$C$5),"CHECK CODE") -> Europe | V13: €1050 | W13: =_xlfn.IFNA(_xlfn.XLOOKUP(Table3[[#This Row],[Country Code]],Lookups!$A$2:$A$5,Lookups!$D$2:$D$5),"CHECK CODE") -> EUR | X13: =VALUE(MID(Table3[[#This Row],[Unit Price]],2,50)) -> 1050 | Y13: =_xlfn.IFNA(_xlfn.XLOOKUP(Table3[[#This Row],[Country Code]],Lookups!$A$2:$A$5,Lookups!$E$2:$E$5),"") -> 1 | Z13: =Table3[[#This Row],[Unit Price (local)]]/Table3[[#This Row],[FX Rate (per EUR)]] -> 1050 | AA13: 180 | AB13: 10 | AC13: =ROUND(Table3[[#This Row],[Unit Price (EUR)]]*Table3[[#This Row],[Units Sold]],0) -> 189000 | AD13: =ROUND(Table3[[#This Row],[Gross Sales (EUR)]]*(1-Table3[[#This Row],[Discount (%)]]/100),0) -> 170100 | AE13: =_xlfn.IFNA(_xlfn.XLOOKUP(Table3[[#This Row],[Month]],Lookups!$N$2:$N$13,Lookups!$O$2:$O$13),"CHECK MONTH") -> 1 | AF13: =TEXT(Table3[[#This Row],[Month No]],"00")&" - "&Table3[[#This Row],[Month]] -> 01 - January | AG13: =_xlfn.IFNA(_xlfn.XLOOKUP(Table3[[#This Row],[Month]],Lookups!$N$2:$N$13,Lookups!$P$2:$P$13),"CHECK MONTH") -> Q1 | AH13: =Table3[[#This Row],[Gross Sales (EUR)]]-Table3[[#This Row],[Total Sales (EUR)]] -> 18900 | AI13: =DATE(Lookups!$O$15,Table3[[#This Row],[Month No]],1) -> 45658
A14: 13 | B14: Sanya | C14: Joshi | D14: =TRIM(Table3[[#This Row],[Rep Last Name]])&", "&TRIM(Table3[[#This Row],[Rep First Name]]) -> Joshi, Sanya | E14: February | F14: Electric Unicycle | G14: 15 mph | H14: =IF(Table3[[#This Row],[Min Speed (original, incomplete)]]="",_xlfn.IFNA(_xlfn.XLOOKUP(Table3[[#This Row],[Product Type]],Lookups!$G$2:$G$4,Lookups!$H$2:$H$4),"CHECK PRODUCT"),Table3[[#This Row],[Min Speed (original, incomplete)]]) -> 15 mph | I14: 30 mph | J14: 30 miles | K14: =ROUND(VALUE(SUBSTITUTE(Table3[[#This Row],[Min Speed (mph)]]," mph",""))*Lookups!$L$2,0) -> 24 | L14: =ROUND(VALUE(SUBSTITUTE(Table3[[#This Row],[Speed]]," mph",""))*Lookups!$L$2,0) -> 48 | M14: =Table3[[#This Row],[Min Speed (km/h)]]&" – "&Table3[[#This Row],[Max Speed (km/h)]]&" km/h" -> 24 – 48 km/h | N14: =IF(ISNUMBER(SEARCH("mile",Table3[[#This Row],[Distance]])),ROUND(VALUE(SUBSTITUTE(Table3[[#This Row],[Distance]]," miles",""))*Lookups!$L$3,0),ROUND(VALUE(SUBSTITUTE(Table3[[#This Row],[Distance]]," meters",""))*Lookups!$L$4,0)) -> 48 | O14: 456 Brigade Road, Bengaluru, 560001 | P14: =TRIM(LEFT(Table3[[#This Row],[Shipping Address]],FIND(",",Table3[[#This Row],[Shipping Address]])-1)) -> 456 Brigade Road | Q14: =TRIM(MID(Table3[[#This Row],[Shipping Address]],FIND(",",Table3[[#This Row],[Shipping Address]])+1,FIND(",",Table3[[#This Row],[Shipping Address]],FIND(",",Table3[[#This Row],[Shipping Address]])+1)-FIND(",",Table3[[#This Row],[Shipping Address]])-1)) -> Bengaluru | R14: =TRIM(MID(Table3[[#This Row],[Shipping Address]],FIND(",",Table3[[#This Row],[Shipping Address]],FIND(",",Table3[[#This Row],[Shipping Address]])+1)+1,20)) -> 560001 | S14: IN | T14: =_xlfn.IFNA(_xlfn.XLOOKUP(Table3[[#This Row],[Country Code]],Lookups!$A$2:$A$5,Lookups!$B$2:$B$5),"CHECK CODE") -> India | U14: =_xlfn.IFNA(_xlfn.XLOOKUP(Table3[[#This Row],[Country Code]],Lookups!$A$2:$A$5,Lookups!$C$2:$C$5),"CHECK CODE") -> Asia | V14: ₹30,000 | W14: =_xlfn.IFNA(_xlfn.XLOOKUP(Table3[[#This Row],[Country Code]],Lookups!$A$2:$A$5,Lookups!$D$2:$D$5),"CHECK CODE") -> INR | X14: =VALUE(MID(Table3[[#This Row],[Unit Price]],2,50)) -> 30000 | Y14: =_xlfn.IFNA(_xlfn.XLOOKUP(Table3[[#This Row],[Country Code]],Lookups!$A$2:$A$5,Lookups!$E$2:$E$5),"") -> 109.882 | Z14: =Table3[[#This Row],[Unit Price (local)]]/Table3[[#This Row],[FX Rate (per EUR)]] -> 273.02015 | AA14: 160 | AB14: 0 | AC14: =ROUND(Table3[[#This Row],[Unit Price (EUR)]]*Table3[[#This Row],[Units Sold]],0) -> 43683 | AD14: =ROUND(Table3[[#This Row],[Gross Sales (EUR)]]*(1-Table3[[#This Row],[Discount (%)]]/100),0) -> 43683 | AE14: =_xlfn.IFNA(_xlfn.XLOOKUP(Table3[[#This Row],[Month]],Lookups!$N$2:$N$13,Lookups!$O$2:$O$13),"CHECK MONTH") -> 2 | AF14: =TEXT(Table3[[#This Row],[Month No]],"00")&" - "&Table3[[#This Row],[Month]] -> 02 - February | AG14: =_xlfn.IFNA(_xlfn.XLOOKUP(Table3[[#This Row],[Month]],Lookups!$N$2:$N$13,Lookups!$P$2:$P$13),"CHECK MONTH") -> Q1 | AH14: =Table3[[#This Row],[Gross Sales (EUR)]]-Table3[[#This Row],[Total Sales (EUR)]] -> 0 | AI14: =DATE(Lookups!$O$15,Table3[[#This Row],[Month No]],1) -> 45689
A15: 14 | B15: Sanya | C15: Joshi | D15: =TRIM(Table3[[#This Row],[Rep Last Name]])&", "&TRIM(Table3[[#This Row],[Rep First Name]]) -> Joshi, Sanya | E15: February | F15: Electric Scooter | H15: =IF(Table3[[#This Row],[Min Speed (original, incomplete)]]="",_xlfn.IFNA(_xlfn.XLOOKUP(Table3[[#This Row],[Product Type]],Lookups!$G$2:$G$4,Lookups!$H$2:$H$4),"CHECK PRODUCT"),Table3[[#This Row],[Min Speed (original, incomplete)]]) -> 20 mph | I15: 35 mph | J15: 40 miles | K15: =ROUND(VALUE(SUBSTITUTE(Table3[[#This Row],[Min Speed (mph)]]," mph",""))*Lookups!$L$2,0) -> 32 | L15: =ROUND(VALUE(SUBSTITUTE(Table3[[#This Row],[Speed]]," mph",""))*Lookups!$L$2,0) -> 56 | M15: =Table3[[#This Row],[Min Speed (km/h)]]&" – "&Table3[[#This Row],[Max Speed (km/h)]]&" km/h" -> 32 – 56 km/h | N15: =IF(ISNUMBER(SEARCH("mile",Table3[[#This Row],[Distance]])),ROUND(VALUE(SUBSTITUTE(Table3[[#This Row],[Distance]]," miles",""))*Lookups!$L$3,0),ROUND(VALUE(SUBSTITUTE(Table3[[#This Row],[Distance]]," meters",""))*Lookups!$L$4,0)) -> 64 | O15: 457 Brigade Road, Bengaluru, 560001 | P15: =TRIM(LEFT(Table3[[#This Row],[Shipping Address]],FIND(",",Table3[[#This Row],[Shipping Address]])-1)) -> 457 Brigade Road | Q15: =TRIM(MID(Table3[[#This Row],[Shipping Address]],FIND(",",Table3[[#This Row],[Shipping Address]])+1,FIND(",",Table3[[#This Row],[Shipping Address]],FIND(",",Table3[[#This Row],[Shipping Address]])+1)-FIND(",",Table3[[#This Row],[Shipping Address]])-1)) -> Bengaluru | R15: =TRIM(MID(Table3[[#This Row],[Shipping Address]],FIND(",",Table3[[#This Row],[Shipping Address]],FIND(",",Table3[[#This Row],[Shipping Address]])+1)+1,20)) -> 560001 | S15: IN | T15: =_xlfn.IFNA(_xlfn.XLOOKUP(Table3[[#This Row],[Country Code]],Lookups!$A$2:$A$5,Lookups!$B$2:$B$5),"CHECK CODE") -> India | U15: =_xlfn.IFNA(_xlfn.XLOOKUP(Table3[[#This Row],[Country Code]],Lookups!$A$2:$A$5,Lookups!$C$2:$C$5),"CHECK CODE") -> Asia | V15: ₹25,000 | W15: =_xlfn.IFNA(_xlfn.XLOOKUP(Table3[[#This Row],[Country Code]],Lookups!$A$2:$A$5,Lookups!$D$2:$D$5),"CHECK CODE") -> INR | X15: =VALUE(MID(Table3[[#This Row],[Unit Price]],2,50)) -> 25000 | Y15: =_xlfn.IFNA(_xlfn.XLOOKUP(Table3[[#This Row],[Country Code]],Lookups!$A$2:$A$5,Lookups!$E$2:$E$5),"") -> 109.882 | Z15: =Table3[[#This Row],[Unit Price (local)]]/Table3[[#This Row],[FX Rate (per EUR)]] -> 227.51679 | AA15: 350 | AB15: 0 | AC15: =ROUND(Table3[[#This Row],[Unit Price (EUR)]]*Table3[[#This Row],[Units Sold]],0) -> 79631 | AD15: =ROUND(Table3[[#This Row],[Gross Sales (EUR)]]*(1-Table3[[#This Row],[Discount (%)]]/100),0) -> 79631 | AE15: =_xlfn.IFNA(_xlfn.XLOOKUP(Table3[[#This Row],[Month]],Lookups!$N$2:$N$13,Lookups!$O$2:$O$13),"CHECK MONTH") -> 2 | AF15: =TEXT(Table3[[#This Row],[Month No]],"00")&" - "&Table3[[#This Row],[Month]] -> 02 - February | AG15: =_xlfn.IFNA(_xlfn.XLOOKUP(Table3[[#This Row],[Month]],Lookups!$N$2:$N$13,Lookups!$P$2:$P$13),"CHECK MONTH") -> Q1 | AH15: =Table3[[#This Row],[Gross Sales (EUR)]]-Table3[[#This Row],[Total Sales (EUR)]] -> 0 | AI15: =DATE(Lookups!$O$15,Table3[[#This Row],[Month No]],1) -> 45689
A16: 15 | B16: Sanya | C16: Joshi | D16: =TRIM(Table3[[#This Row],[Rep Last Name]])&", "&TRIM(Table3[[#This Row],[Rep First Name]]) -> Joshi, Sanya | E16: February | F16: Electric Skateboard | G16: 18 mph | H16: =IF(Table3[[#This Row],[Min Speed (original, incomplete)]]="",_xlfn.IFNA(_xlfn.XLOOKUP(Table3[[#This Row],[Product Type]],Lookups!$G$2:$G$4,Lookups!$H$2:$H$4),"CHECK PRODUCT"),Table3[[#This Row],[Min Speed (original, incomplete)]]) -> 18 mph | I16: 28 mph | J16: 25 miles | K16: =ROUND(VALUE(SUBSTITUTE(Table3[[#This Row],[Min Speed (mph)]]," mph",""))*Lookups!$L$2,0) -> 29 | L16: =ROUND(VALUE(SUBSTITUTE(Table3[[#This Row],[Speed]]," mph",""))*Lookups!$L$2,0) -> 45 | M16: =Table3[[#This Row],[Min Speed (km/h)]]&" – "&Table3[[#This Row],[Max Speed (km/h)]]&" km/h" -> 29 – 45 km/h | N16: =IF(ISNUMBER(SEARCH("mile",Table3[[#This Row],[Distance]])),ROUND(VALUE(SUBSTITUTE(Table3[[#This Row],[Distance]]," miles",""))*Lookups!$L$3,0),ROUND(VALUE(SUBSTITUTE(Table3[[#This Row],[Distance]]," meters",""))*Lookups!$L$4,0)) -> 40 | O16: 458 Brigade Road, Bengaluru, 560001 | P16: =TRIM(LEFT(Table3[[#This Row],[Shipping Address]],FIND(",",Table3[[#This Row],[Shipping Address]])-1)) -> 458 Brigade Road | Q16: =TRIM(MID(Table3[[#This Row],[Shipping Address]],FIND(",",Table3[[#This Row],[Shipping Address]])+1,FIND(",",Table3[[#This Row],[Shipping Address]],FIND(",",Table3[[#This Row],[Shipping Address]])+1)-FIND(",",Table3[[#This Row],[Shipping Address]])-1)) -> Bengaluru | R16: =TRIM(MID(Table3[[#This Row],[Shipping Address]],FIND(",",Table3[[#This Row],[Shipping Address]],FIND(",",Table3[[#This Row],[Shipping Address]])+1)+1,20)) -> 560001 | S16: IN | T16: =_xlfn.IFNA(_xlfn.XLOOKUP(Table3[[#This Row],[Country Code]],Lookups!$A$2:$A$5,Lookups!$B$2:$B$5),"CHECK CODE") -> India | U16: =_xlfn.IFNA(_xlfn.XLOOKUP(Table3[[#This Row],[Country Code]],Lookups!$A$2:$A$5,Lookups!$C$2:$C$5),"CHECK CODE") -> Asia | V16: ₹22,000 | W16: =_xlfn.IFNA(_xlfn.XLOOKUP(Table3[[#This Row],[Country Code]],Lookups!$A$2:$A$5,Lookups!$D$2:$D$5),"CHECK CODE") -> INR | X16: =VALUE(MID(Table3[[#This Row],[Unit Price]],2,50)) -> 22000 | Y16: =_xlfn.IFNA(_xlfn.XLOOKUP(Table3[[#This Row],[Country Code]],Lookups!$A$2:$A$5,Lookups!$E$2:$E$5),"") -> 109.882 | Z16: =Table3[[#This Row],[Unit Price (local)]]/Table3[[#This Row],[FX Rate (per EUR)]] -> 200.21478 | AA16: 220 | AB16: 0 | AC16: =ROUND(Table3[[#This Row],[Unit Price (EUR)]]*Table3[[#This Row],[Units Sold]],0) -> 44047 | AD16: =ROUND(Table3[[#This Row],[Gross Sales (EUR)]]*(1-Table3[[#This Row],[Discount (%)]]/100),0) -> 44047 | AE16: =_xlfn.IFNA(_xlfn.XLOOKUP(Table3[[#This Row],[Month]],Lookups!$N$2:$N$13,Lookups!$O$2:$O$13),"CHECK MONTH") -> 2 | AF16: =TEXT(Table3[[#This Row],[Month No]],"00")&" - "&Table3[[#This Row],[Month]] -> 02 - February | AG16: =_xlfn.IFNA(_xlfn.XLOOKUP(Table3[[#This Row],[Month]],Lookups!$N$2:$N$13,Lookups!$P$2:$P$13),"CHECK MONTH") -> Q1 | AH16: =Table3[[#This Row],[Gross Sales (EUR)]]-Table3[[#This Row],[Total Sales (EUR)]] -> 0 | AI16: =DATE(Lookups!$O$15,Table3[[#This Row],[Month No]],1) -> 45689
A17: 16 | B17: Fang | C17: Liu | D17: =TRIM(Table3[[#This Row],[Rep Last Name]])&", "&TRIM(Table3[[#This Row],[Rep First Name]]) -> Liu, Fang | E17: February | F17: Electric Unicycle | G17: 15 mph | H17: =IF(Table3[[#This Row],[Min Speed (original, incomplete)]]="",_xlfn.IFNA(_xlfn.XLOOKUP(Table3[[#This Row],[Product Type]],Lookups!$G$2:$G$4,Lookups!$H$2:$H$4),"CHECK PRODUCT"),Table3[[#This Row],[Min Speed (original, incomplete)]]) -> 15 mph | I17: 30 mph | J17: 48,280 meters | K17: =ROUND(VALUE(SUBSTITUTE(Table3[[#This Row],[Min Speed (mph)]]," mph",""))*Lookups!$L$2,0) -> 24 | L17: =ROUND(VALUE(SUBSTITUTE(Table3[[#This Row],[Speed]]," mph",""))*Lookups!$L$2,0) -> 48 | M17: =Table3[[#This Row],[Min Speed (km/h)]]&" – "&Table3[[#This Row],[Max Speed (km/h)]]&" km/h" -> 24 – 48 km/h | N17: =IF(ISNUMBER(SEARCH("mile",Table3[[#This Row],[Distance]])),ROUND(VALUE(SUBSTITUTE(Table3[[#This Row],[Distance]]," miles",""))*Lookups!$L$3,0),ROUND(VALUE(SUBSTITUTE(Table3[[#This Row],[Distance]]," meters",""))*Lookups!$L$4,0)) -> 48 | O17: 99 Nanjing Road, Shanghai, 200001 | P17: =TRIM(LEFT(Table3[[#This Row],[Shipping Address]],FIND(",",Table3[[#This Row],[Shipping Address]])-1)) -> 99 Nanjing Road | Q17: =TRIM(MID(Table3[[#This Row],[Shipping Address]],FIND(",",Table3[[#This Row],[Shipping Address]])+1,FIND(",",Table3[[#This Row],[Shipping Address]],FIND(",",Table3[[#This Row],[Shipping Address]])+1)-FIND(",",Table3[[#This Row],[Shipping Address]])-1)) -> Shanghai | R17: =TRIM(MID(Table3[[#This Row],[Shipping Address]],FIND(",",Table3[[#This Row],[Shipping Address]],FIND(",",Table3[[#This Row],[Shipping Address]])+1)+1,20)) -> 200001 | S17: CN | T17: =_xlfn.IFNA(_xlfn.XLOOKUP(Table3[[#This Row],[Country Code]],Lookups!$A$2:$A$5,Lookups!$B$2:$B$5),"CHECK CODE") -> China | U17: =_xlfn.IFNA(_xlfn.XLOOKUP(Table3[[#This Row],[Country Code]],Lookups!$A$2:$A$5,Lookups!$C$2:$C$5),"CHECK CODE") -> Asia | V17: ¥5,000 | W17: =_xlfn.IFNA(_xlfn.XLOOKUP(Table3[[#This Row],[Country Code]],Lookups!$A$2:$A$5,Lookups!$D$2:$D$5),"CHECK CODE") -> CNY | X17: =VALUE(MID(Table3[[#This Row],[Unit Price]],2,50)) -> 5000 | Y17: =_xlfn.IFNA(_xlfn.XLOOKUP(Table3[[#This Row],[Country Code]],Lookups!$A$2:$A$5,Lookups!$E$2:$E$5),"") -> 7.7255 | Z17: =Table3[[#This Row],[Unit Price (local)]]/Table3[[#This Row],[FX Rate (per EUR)]] -> 647.2073 | AA17: 550 | AB17: 0 | AC17: =ROUND(Table3[[#This Row],[Unit Price (EUR)]]*Table3[[#This Row],[Units Sold]],0) -> 355964 | AD17: =ROUND(Table3[[#This Row],[Gross Sales (EUR)]]*(1-Table3[[#This Row],[Discount (%)]]/100),0) -> 355964 | AE17: =_xlfn.IFNA(_xlfn.XLOOKUP(Table3[[#This Row],[Month]],Lookups!$N$2:$N$13,Lookups!$O$2:$O$13),"CHECK MONTH") -> 2 | AF17: =TEXT(Table3[[#This Row],[Month No]],"00")&" - "&Table3[[#This Row],[Month]] -> 02 - February | AG17: =_xlfn.IFNA(_xlfn.XLOOKUP(Table3[[#This Row],[Month]],Lookups!$N$2:$N$13,Lookups!$P$2:$P$13),"CHECK MONTH") -> Q1 | AH17: =Table3[[#This Row],[Gross Sales (EUR)]]-Table3[[#This Row],[Total Sales (EUR)]] -> 0 | AI17: =DATE(Lookups!$O$15,Table3[[#This Row],[Month No]],1) -> 45689
A18: 17 | B18: Fang | C18: Liu | D18: =TRIM(Table3[[#This Row],[Rep Last Name]])&", "&TRIM(Table3[[#This Row],[Rep First Name]]) -> Liu, Fang | E18: February | F18: Electric Scooter | G18: 20 mph | H18: =IF(Table3[[#This Row],[Min Speed (original, incomplete)]]="",_xlfn.IFNA(_xlfn.XLOOKUP(Table3[[#This Row],[Product Type]],Lookups!$G$2:$G$4,Lookups!$H$2:$H$4),"CHECK PRODUCT"),Table3[[#This Row],[Min Speed (original, incomplete)]]) -> 20 mph | I18: 35 mph | J18: 40 miles | K18: =ROUND(VALUE(SUBSTITUTE(Table3[[#This Row],[Min Speed (mph)]]," mph",""))*Lookups!$L$2,0) -> 32 | L18: =ROUND(VALUE(SUBSTITUTE(Table3[[#This Row],[Speed]]," mph",""))*Lookups!$L$2,0) -> 56 | M18: =Table3[[#This Row],[Min Speed (km/h)]]&" – "&Table3[[#This Row],[Max Speed (km/h)]]&" km/h" -> 32 – 56 km/h | N18: =IF(ISNUMBER(SEARCH("mile",Table3[[#This Row],[Distance]])),ROUND(VALUE(SUBSTITUTE(Table3[[#This Row],[Distance]]," miles",""))*Lookups!$L$3,0),ROUND(VALUE(SUBSTITUTE(Table3[[#This Row],[Distance]]," meters",""))*Lookups!$L$4,0)) -> 64 | O18: 100 Nanjing Road, Shanghai, 200001 | P18: =TRIM(LEFT(Table3[[#This Row],[Shipping Address]],FIND(",",Table3[[#This Row],[Shipping Address]])-1)) -> 100 Nanjing Road | Q18: =TRIM(MID(Table3[[#This Row],[Shipping Address]],FIND(",",Table3[[#This Row],[Shipping Address]])+1,FIND(",",Table3[[#This Row],[Shipping Address]],FIND(",",Table3[[#This Row],[Shipping Address]])+1)-FIND(",",Table3[[#This Row],[Shipping Address]])-1)) -> Shanghai | R18: =TRIM(MID(Table3[[#This Row],[Shipping Address]],FIND(",",Table3[[#This Row],[Shipping Address]],FIND(",",Table3[[#This Row],[Shipping Address]])+1)+1,20)) -> 200001 | S18: CN | T18: =_xlfn.IFNA(_xlfn.XLOOKUP(Table3[[#This Row],[Country Code]],Lookups!$A$2:$A$5,Lookups!$B$2:$B$5),"CHECK CODE") -> China | U18: =_xlfn.IFNA(_xlfn.XLOOKUP(Table3[[#This Row],[Country Code]],Lookups!$A$2:$A$5,Lookups!$C$2:$C$5),"CHECK CODE") -> Asia | V18: ¥3,500 | W18: =_xlfn.IFNA(_xlfn.XLOOKUP(Table3[[#This Row],[Country Code]],Lookups!$A$2:$A$5,Lookups!$D$2:$D$5),"CHECK CODE") -> CNY | X18: =VALUE(MID(Table3[[#This Row],[Unit Price]],2,50)) -> 3500 | Y18: =_xlfn.IFNA(_xlfn.XLOOKUP(Table3[[#This Row],[Country Code]],Lookups!$A$2:$A$5,Lookups!$E$2:$E$5),"") -> 7.7255 | Z18: =Table3[[#This Row],[Unit Price (local)]]/Table3[[#This Row],[FX Rate (per EUR)]] -> 453.04511 | AA18: 1200 | AB18: 0 | AC18: =ROUND(Table3[[#This Row],[Unit Price (EUR)]]*Table3[[#This Row],[Units Sold]],0) -> 543654 | AD18: =ROUND(Table3[[#This Row],[Gross Sales (EUR)]]*(1-Table3[[#This Row],[Discount (%)]]/100),0) -> 543654 | AE18: =_xlfn.IFNA(_xlfn.XLOOKUP(Table3[[#This Row],[Month]],Lookups!$N$2:$N$13,Lookups!$O$2:$O$13),"CHECK MONTH") -> 2 | AF18: =TEXT(Table3[[#This Row],[Month No]],"00")&" - "&Table3[[#This Row],[Month]] -> 02 - February | AG18: =_xlfn.IFNA(_xlfn.XLOOKUP(Table3[[#This Row],[Month]],Lookups!$N$2:$N$13,Lookups!$P$2:$P$13),"CHECK MONTH") -> Q1 | AH18: =Table3[[#This Row],[Gross Sales (EUR)]]-Table3[[#This Row],[Total Sales (EUR)]] -> 0 | AI18: =DATE(Lookups!$O$15,Table3[[#This Row],[Month No]],1) -> 45689
